Workbook

Sheet Project Details
A1: THE HABITAINER — PROJECT SETUP TEMPLATE | Fill and upload to HStack
A2: Version 1.0 | This file is downloaded from HStack when a new project is approved. Project Details (grey fields) are pre-filled from the app. Fill white fields only. Upload via Projects → [Project] → Overview → Upload Project Setup.
A3: 🔒 Grey = Pre-filled from HStack (do not change) ✏ White = Fill this in 🔽 = Dropdown — click to select ₹ = Enter number only, no commas
A5: PROJECT IDENTIFICATION
A6: Project Code | B6: ALTR/2026/XXX
A7: Project Name
A8: Division
A9: Production System
A10: Client Name
A11: Client Email
A12: Client Phone
A13: Site Location
A14: Site City
A15: Site State
A16: Sales Owner | B16: John Kunnath
A17: Project Manager | B17: Suraj Rao
A19: COMMERCIAL DETAILS
A20: Contract Value (₹)
A21: Contract Start Date
A22: Expected Delivery Date
A23: Number of Modules
A24: Number of Panels
A25: GST Applicable | B25: Yes
A26: GST Rate (%) | B26: 18
A28: TEAM ASSIGNMENT
A29: Production Head | B29: Azad Ali
A30: Site Installation Manager | B30: Awaiz Ahmed
A31: Planning Engineer | B31: Karthik
A32: Costing Engineer | B32: Mohammed Nakeem
A33: Operations Architect | B33: Venkat

Sheet BOQ + Margin
A1: BOQ — BILL OF QUANTITIES | Tender + GFC Quantities & Rates | Auto-calculates Margins
A2: ℹ Blue columns = Tender (fill at project start). Teal columns = GFC (fill after H1 sign-off). Black columns = auto-calculated (do not edit). All rates in ₹ per unit.
A3: ITEM DETAILS | E3: TENDER | F3: GFC | G3: QUANTITY | I3: RATES (₹) | M3: AMOUNTS (₹) | O3: MARGIN | P3: SCOPE
A4: S.No | B4: Category | C4: Item Description | D4: Unit | E4: Tender Qty | F4: GFC Qty | G4: Wastage % | H4: BOQ Qty (auto) | I4: Material Rate ₹ | J4: Labour Rate ₹ | K4: OH Rate ₹ | L4: BOQ Rate ₹ (auto) | M4: Tender Amount ₹ | N4: GFC Amount ₹ | O4: Margin % | P4: Scope
A5: ▶ SUB-FRAME FABRICATION
A6: 1 | B6: Sub-Frame Fabrication | C6: Structural steel — Beams, Columns / Framed Structure | D6: KG | G6: 0.05 | H6: =IF(F6>0,F6*(1+G6),E6*(1+G6)) | L6: =I6+J6+K6 | M6: =IF(E6>0,E6*L6,0) | N6: =IF(F6>0,H6*L6,0) | P6: Habitainer
A7: 2 | B7: Sub-Frame Fabrication | C7: LGSF — Wall framing | D7: KG | G7: 0.05 | H7: =IF(F7>0,F7*(1+G7),E7*(1+G7)) | L7: =I7+J7+K7 | M7: =IF(E7>0,E7*L7,0) | N7: =IF(F7>0,H7*L7,0) | P7: Habitainer
A8: 3 | B8: Sub-Frame Fabrication | C8: LGSF — C-Channel sections | D8: KG | G8: 0.05 | H8: =IF(F8>0,F8*(1+G8),E8*(1+G8)) | L8: =I8+J8+K8 | M8: =IF(E8>0,E8*L8,0) | N8: =IF(F8>0,H8*L8,0) | P8: Habitainer
A9: ▶ STRUCTURAL / MAIN FRAME
A10: 4 | B10: Structural / Main Frame | C10: Deck Sheet 1.0mm — Floor & Roof | D10: KG | G10: 0.05 | H10: =IF(F10>0,F10*(1+G10),E10*(1+G10)) | L10: =I10+J10+K10 | M10: =IF(E10>0,E10*L10,0) | N10: =IF(F10>0,H10*L10,0) | P10: Habitainer
A11: 5 | B11: Structural / Main Frame | C11: Welded Wire Mesh 2.5mm 50mm C/C | D11: KG | G11: 0.05 | H11: =IF(F11>0,F11*(1+G11),E11*(1+G11)) | L11: =I11+J11+K11 | M11: =IF(E11>0,E11*L11,0) | N11: =IF(F11>0,H11*L11,0) | P11: Habitainer
A12: 6 | B12: Structural / Main Frame | C12: Chicken Wire Mesh 1mm 25mm | D12: KG | G12: 0.05 | H12: =IF(F12>0,F12*(1+G12),E12*(1+G12)) | L12: =I12+J12+K12 | M12: =IF(E12>0,E12*L12,0) | N12: =IF(F12>0,H12*L12,0) | P12: Habitainer
A13: 7 | B13: Structural / Main Frame | C13: EPS Thermocol Sheet | D13: Nos | G13: 0.05 | H13: =IF(F13>0,F13*(1+G13),E13*(1+G13)) | L13: =I13+J13+K13 | M13: =IF(E13>0,E13*L13,0) | N13: =IF(F13>0,H13*L13,0) | P13: Habitainer
A14: 8 | B14: Structural / Main Frame | C14: Self Drilling Screws | D14: Nos | G14: 0.05 | H14: =IF(F14>0,F14*(1+G14),E14*(1+G14)) | L14: =I14+J14+K14 | M14: =IF(E14>0,E14*L14,0) | N14: =IF(F14>0,H14*L14,0) | P14: Habitainer
A15: 9 | B15: Structural / Main Frame | C15: Roofing Concrete Plain Cement Mortar | D15: CFT | G15: 0.05 | H15: =IF(F15>0,F15*(1+G15),E15*(1+G15)) | L15: =I15+J15+K15 | M15: =IF(E15>0,E15*L15,0) | N15: =IF(F15>0,H15*L15,0) | P15: Habitainer
A16: ▶ INSULATION
A17: 10 | B17: Insulation | C17: Rockwool Slab 48kg 50mm — Inner Wall | D17: SFT | G17: 0.05 | H17: =IF(F17>0,F17*(1+G17),E17*(1+G17)) | L17: =I17+J17+K17 | M17: =IF(E17>0,E17*L17,0) | N17: =IF(F17>0,H17*L17,0) | P17: Habitainer
A18: 11 | B18: Insulation | C18: 4mm Aluminium Bubble Wrap Heat Barrier | D18: SQM | G18: 0.05 | H18: =IF(F18>0,F18*(1+G18),E18*(1+G18)) | L18: =I18+J18+K18 | M18: =IF(E18>0,E18*L18,0) | N18: =IF(F18>0,H18*L18,0) | P18: Habitainer
A19: ▶ INTERNAL WALL PANELLING
A20: 12 | B20: Internal Wall Panelling | C20: Saint-Gobain Habit Board 13mm — Inner Wall | D20: SFT | G20: 0.05 | H20: =IF(F20>0,F20*(1+G20),E20*(1+G20)) | L20: =I20+J20+K20 | M20: =IF(E20>0,E20*L20,0) | N20: =IF(F20>0,H20*L20,0) | P20: Habitainer
A21: 13 | B21: Internal Wall Panelling | C21: Toilet Cement Board | D21: SFT | G21: 0.05 | H21: =IF(F21>0,F21*(1+G21),E21*(1+G21)) | L21: =I21+J21+K21 | M21: =IF(E21>0,E21*L21,0) | N21: =IF(F21>0,H21*L21,0) | P21: Habitainer
A22: 14 | B22: Internal Wall Panelling | C22: Jointing Compound | D22: KG | G22: 0.05 | H22: =IF(F22>0,F22*(1+G22),E22*(1+G22)) | L22: =I22+J22+K22 | M22: =IF(E22>0,E22*L22,0) | N22: =IF(F22>0,H22*L22,0) | P22: Habitainer
A23: 15 | B23: Internal Wall Panelling | C23: Corner Tape | D23: MTR | G23: 0.05 | H23: =IF(F23>0,F23*(1+G23),E23*(1+G23)) | L23: =I23+J23+K23 | M23: =IF(E23>0,E23*L23,0) | N23: =IF(F23>0,H23*L23,0) | P23: Habitainer
A24: ▶ EXTERNAL CLADDING
A25: 16 | B25: External Cladding | C25: Shera Neu Wall Board 2440x1220x10mm — External | D25: SFT | G25: 0.05 | H25: =IF(F25>0,F25*(1+G25),E25*(1+G25)) | L25: =I25+J25+K25 | M25: =IF(E25>0,E25*L25,0) | N25: =IF(F25>0,H25*L25,0) | P25: Habitainer
A26: 17 | B26: External Cladding | C26: Shera Plank — Exterior Finish | D26: SFT | G26: 0.05 | H26: =IF(F26>0,F26*(1+G26),E26*(1+G26)) | L26: =I26+J26+K26 | M26: =IF(E26>0,E26*L26,0) | N26: =IF(F26>0,H26*L26,0) | P26: Habitainer
A27: 18 | B27: External Cladding | C27: Silicon Sealant — External Joints | D27: Tubes | G27: 0.05 | H27: =IF(F27>0,F27*(1+G27),E27*(1+G27)) | L27: =I27+J27+K27 | M27: =IF(E27>0,E27*L27,0) | N27: =IF(F27>0,H27*L27,0) | P27: Habitainer
A28: ▶ CEILING
A29: 19 | B29: Ceiling | C29: Gypsum Board 12.5mm — Ceiling | D29: SFT | G29: 0.05 | H29: =IF(F29>0,F29*(1+G29),E29*(1+G29)) | L29: =I29+J29+K29 | M29: =IF(E29>0,E29*L29,0) | N29: =IF(F29>0,H29*L29,0) | P29: Habitainer
A30: 20 | B30: Ceiling | C30: Moisture-Resistant Gypsum — Toilets | D30: SFT | G30: 0.05 | H30: =IF(F30>0,F30*(1+G30),E30*(1+G30)) | L30: =I30+J30+K30 | M30: =IF(E30>0,E30*L30,0) | N30: =IF(F30>0,H30*L30,0) | P30: Habitainer
A31: 21 | B31: Ceiling | C31: Ceiling Grid Frame | D31: SFT | G31: 0.05 | H31: =IF(F31>0,F31*(1+G31),E31*(1+G31)) | L31: =I31+J31+K31 | M31: =IF(E31>0,E31*L31,0) | N31: =IF(F31>0,H31*L31,0) | P31: Habitainer
A32: ▶ FLOORING
A33: 22 | B33: Flooring | C33: Vitrified Flooring and Tile Dadoing | D33: SFT | G33: 0.05 | H33: =IF(F33>0,F33*(1+G33),E33*(1+G33)) | L33: =I33+J33+K33 | M33: =IF(E33>0,E33*L33,0) | N33: =IF(F33>0,H33*L33,0) | P33: Habitainer
A34: 23 | B34: Flooring | C34: Wooden Flooring — Single Units | D34: SFT | G34: 0.05 | H34: =IF(F34>0,F34*(1+G34),E34*(1+G34)) | L34: =I34+J34+K34 | M34: =IF(E34>0,E34*L34,0) | N34: =IF(F34>0,H34*L34,0) | P34: Habitainer
A35: 24 | B35: Flooring | C35: Tile Adhesive | D35: KG | G35: 0.05 | H35: =IF(F35>0,F35*(1+G35),E35*(1+G35)) | L35: =I35+J35+K35 | M35: =IF(E35>0,E35*L35,0) | N35: =IF(F35>0,H35*L35,0) | P35: Habitainer
A36: 25 | B36: Flooring | C36: Tile Grout | D36: KG | G36: 0.05 | H36: =IF(F36>0,F36*(1+G36),E36*(1+G36)) | L36: =I36+J36+K36 | M36: =IF(E36>0,E36*L36,0) | N36: =IF(F36>0,H36*L36,0) | P36: Habitainer
A37: 26 | B37: Flooring | C37: Waterproofing Membrane | D37: SQM | G37: 0.05 | H37: =IF(F37>0,F37*(1+G37),E37*(1+G37)) | L37: =I37+J37+K37 | M37: =IF(E37>0,E37*L37,0) | N37: =IF(F37>0,H37*L37,0) | P37: Habitainer
A38: ▶ PAINTING
A39: 27 | B39: Painting | C39: Internal Painting (Compound, Putty 2 coat, Primer 1, Paint 2) | D39: SFT | G39: 0.05 | H39: =IF(F39>0,F39*(1+G39),E39*(1+G39)) | L39: =I39+J39+K39 | M39: =IF(E39>0,E39*L39,0) | N39: =IF(F39>0,H39*L39,0) | P39: Habitainer
A40: 28 | B40: Painting | C40: Waterproof Paint — Wet Areas (2 coats) | D40: SFT | G40: 0.05 | H40: =IF(F40>0,F40*(1+G40),E40*(1+G40)) | L40: =I40+J40+K40 | M40: =IF(E40>0,E40*L40,0) | N40: =IF(F40>0,H40*L40,0) | P40: Habitainer
...

Sheet Project Schedule
A1: PROJECT SCHEDULE — Factory Stages Only | Fill Planned Start & End Dates per Module
A2: ℹ Fill ONLY the white cells (Planned Start and Planned End). Use DD/MM/YYYY format. Mark N/A in the Notes column if a stage does not apply to this project. Site stage dates are filled by Awaiz in HStack 14 days before dispatch.
A3: 🟢 Factory stages — Karthik fills dates 🔵 Site stages — Karthik fills in HStack 14 days before dispatch (14 days before dispatch) — DO NOT fill here
A4: # | B4: Stage Name | C4: Module # (if multi) | D4: Planned Start (DD/MM/YYYY) | E4: Planned End (DD/MM/YYYY) | F4: Duration (Days, auto) | G4: Notes / N/A
A5: FACTORY STAGES — Karthik fills dates
A6: 1 | B6: Main Frame | F6: =IF(AND(D6<>"",E6<>""),E6-D6,"")
A7: 2 | B7: Sub Frame — Panel Production ⟵ parallel to Main Frame | F7: =IF(AND(D7<>"",E7<>""),E7-D7,"")
A8: 3 | B8: Drywall Works Completion | F8: =IF(AND(D8<>"",E8<>""),E8-D8,"")
A9: 4 | B9: MEP Rough In | F9: =IF(AND(D9<>"",E9<>""),E9-D9,"")
A10: 5 | B10: Internal Painting | F10: =IF(AND(D10<>"",E10<>""),E10-D10,"")
A11: 6 | B11: Tiling ⟵ parallel to Internal Painting | F11: =IF(AND(D11<>"",E11<>""),E11-D11,"")
A12: 7 | B12: Exterior Wall Finishing | F12: =IF(AND(D12<>"",E12<>""),E12-D12,"")
A13: 8 | B13: Internal Wall Finishing ⟵ mark N/A if not in scope | F13: =IF(AND(D13<>"",E13<>""),E13-D13,"")
A14: 9 | B14: Carpentry | F14: =IF(AND(D14<>"",E14<>""),E14-D14,"")
A15: 10 | B15: MEP Final | F15: =IF(AND(D15<>"",E15<>""),E15-D15,"")
A16: 11 | B16: Windows & Doors | F16: =IF(AND(D16<>"",E16<>""),E16-D16,"")
A17: 12 | B17: Finishing | F17: =IF(AND(D17<>"",E17<>""),E17-D17,"")
... A20: 15 | B20: Dispatch | F20: =IF(AND(D20<>"",E20<>""),E20-D20,"")
A22: SITE STAGES — Karthik fills in HStack 14 days before dispatch (14 days before dispatch) — leave blank here
A23: 16 | B23: Erection | D23: Karthik fills in HStack 14 days before dispatch | E23: Karthik fills in HStack 14 days before dispatch
A24: 17 | B24: Marriage Line | D24: Karthik fills in HStack 14 days before dispatch | E24: Karthik fills in HStack 14 days before dispatch
A25: 18 | B25: On Site External Finishing | D25: Karthik fills in HStack 14 days before dispatch | E25: Karthik fills in HStack 14 days before dispatch
A26: 19 | B26: Steel Extensions ⟵ mark N/A if not in scope | D26: Karthik fills in HStack 14 days before dispatch | E26: Karthik fills in HStack 14 days before dispatch
A27: 20 | B27: On Site MEP | D27: Karthik fills in HStack 14 days before dispatch | E27: Karthik fills in HStack 14 days before dispatch
A28: 21 | B28: On Site Internal Finishing | D28: Karthik fills in HStack 14 days before dispatch | E28: Karthik fills in HStack 14 days before dispatch
A29: 22 | B29: Snagging (Site) | D29: Karthik fills in HStack 14 days before dispatch | E29: Karthik fills in HStack 14 days before dispatch
A30: 23 | B30: Handover | D30: Karthik fills in HStack 14 days before dispatch | E30: Karthik fills in HStack 14 days before dispatch

Sheet Material Plan
A1: MATERIAL PLAN — Pre-Populated Standard Materials | Fill Tender Qty and Dates
A2: ℹ Standard Habitainer materials are pre-listed. Fill: Tender Qty, PO Release Date, Delivery Date. Add rows for project-specific materials. All dates in DD/MM/YYYY. Status is auto-calculated by HStack after upload.
A3: 🟦 White cells = Fill in 🔒 Grey cells = Pre-filled PO Release Date = when to raise PO with vendor Delivery Date = when material must arrive at factory/site
A4: # | B4: Section | C4: Material | D4: Unit | E4: Tender Qty | F4: Ordered Qty | G4: PO Release Date | H4: Delivery Date (Target) | I4: Destination | J4: Notes
A5: SHELL AND CORE
A6: 1 | B6: Shell and Core | C6: Structural Steel — Beams, Columns / Framed Structure | D6: KG | I6: Factory
A7: 2 | B7: Shell and Core | C7: LGSF — Wall Framing | D7: KG | I7: Factory
A8: 3 | B8: Shell and Core | C8: LGSF — C-Channel Sections | D8: KG | I8: Factory
A9: 4 | B9: Shell and Core | C9: Deck Sheet 1.0mm — Floor & Roof | D9: KG | I9: Factory
A10: 5 | B10: Shell and Core | C10: Welded Wire Mesh 2.5mm 50mm C/C | D10: KG | I10: Factory
A11: 6 | B11: Shell and Core | C11: Chicken Wire Mesh 1mm 25mm | D11: KG | I11: Factory
A12: 7 | B12: Shell and Core | C12: EPS Thermocol Sheet | D12: Nos | I12: Factory
A13: 8 | B13: Shell and Core | C13: Self Drilling Screws | D13: Nos | I13: Factory
A14: 9 | B14: Shell and Core | C14: Roofing Concrete Mix | D14: CFT | I14: Factory
A15: 10 | B15: Shell and Core | C15: Foundation Bolts and Anchor Plates | D15: Nos | I15: Factory
A16: INSULATION & BOARDING
A17: 11 | B17: Insulation & Boarding | C17: Rockwool Slab 48kg 50mm — Inner Wall | D17: SFT | I17: Factory
A18: 12 | B18: Insulation & Boarding | C18: 4mm Aluminium Bubble Wrap Heat Barrier | D18: SQM | I18: Factory
A19: 13 | B19: Insulation & Boarding | C19: Saint-Gobain Habit Board 13mm — Inner Wall | D19: SFT | I19: Factory
A20: 14 | B20: Insulation & Boarding | C20: Toilet Cement Board | D20: SFT | I20: Factory
A21: 15 | B21: Insulation & Boarding | C21: Gypsum Board 12.5mm — Ceiling | D21: SFT | I21: Factory
A22: 16 | B22: Insulation & Boarding | C22: Moisture-Resistant Gypsum — Toilets | D22: SFT | I22: Factory
A23: 17 | B23: Insulation & Boarding | C23: Shera Neu Wall Board 2440x1220x10mm — External | D23: SFT | I23: Factory
A24: 18 | B24: Insulation & Boarding | C24: Shera Plank — Exterior Finish | D24: SFT | I24: Factory
A25: SEALING & WATERPROOFING
A26: 19 | B26: Sealing & Waterproofing | C26: Silicon Sealant — External Joints | D26: Tubes | I26: Factory
A27: 20 | B27: Sealing & Waterproofing | C27: Waterproofing Membrane | D27: SQM | I27: Factory
A28: 21 | B28: Sealing & Waterproofing | C28: Caulking Compound | D28: Tubes | I28: Factory
A29: 22 | B29: Sealing & Waterproofing | C29: Jointing Compound | D29: KG | I29: Factory
A30: 23 | B30: Sealing & Waterproofing | C30: Corner Tape | D30: MTR | I30: Factory
A31: 24 | B31: Sealing & Waterproofing | C31: MS Flashing at Roof/Wall Junctions | D31: Lot | I31: Factory
A32: FLOORING & TILING
A33: 25 | B33: Flooring & Tiling | C33: Vitrified Flooring and Tile Dadoing | D33: SFT | I33: Factory
A34: 26 | B34: Flooring & Tiling | C34: Wooden Flooring — Single Units | D34: SFT | I34: Factory
A35: 27 | B35: Flooring & Tiling | C35: Tile Adhesive | D35: KG | I35: Factory
A36: 28 | B36: Flooring & Tiling | C36: Tile Grout | D36: KG | I36: Factory
A37: 29 | B37: Flooring & Tiling | C37: Rain Water Gutter PVC | D37: MTR | I37: Factory
A38: PAINTING
A39: 30 | B39: Painting | C39: Internal Painting (Compound, Putty, Primer, Paint) | D39: SFT | I39: Factory
A40: 31 | B40: Painting | C40: Waterproof Paint — Wet Areas | D40: SFT | I40: Factory
...

Sheet Billing Milestones
A1: BILLING MILESTONES | Payment Schedule for this Project
A2: ℹ Fill one row per payment milestone. % must total 100. GST Applicable = Y or N. Trigger Event describes what unlocks the invoice (e.g. Work Order Signed, Dispatch, Handover). Amounts are computed by HStack from the contract value after upload.
A3: 🟦 White cells = Fill in Valid GST Applicable values: Y / N Leave # blank to auto-number
A4: # | B4: Milestone Description | C4: % | D4: GST Applicable (Y/N) | E4: Trigger Event
A5: 1 | D5: Y
A6: 2 | D6: Y
A7: 3 | D7: Y
A8: 4 | D8: Y

Sheet Scope of Work
A1: SCOPE OF WORK | Area-wise Responsibility Split
A2: ℹ One row per scope item. Area groups items (e.g. Shell and Core, Interiors, External Works). Scope decides who delivers the item.
A3: Valid Scope values: Habitainer / External Contractor / TBD (TBD or anything else = Not in Scope)
A4: Area | B4: Item | C4: Scope
C5: Habitainer
C6: External Contractor
C7: TBD
